{"trial_id": "4", "hyperparameters": {"space": [{"class_name": "Int", "config": {"name": "units", "default": null, "conditions": [], "min_value": 32, "max_value": 512, "step": 32, "sampling": "linear"}}], "values": {"units": 288}}, "metrics": {"metrics": {}}, "score": null, "best_step": 0, "status": "FAILED", "message": "Traceback (most recent call last):\n  File \"C:\\Users\\Diavolo\\miniconda3\\envs\\DataEnv\\lib\\site-packages\\keras_tuner\\engine\\base_tuner.py\", line 270, in _try_run_and_update_trial\n    self._run_and_update_trial(trial, *fit_args, **fit_kwargs)\n  File \"C:\\Users\\Diavolo\\miniconda3\\envs\\DataEnv\\lib\\site-packages\\keras_tuner\\engine\\base_tuner.py\", line 235, in _run_and_update_trial\n    results = self.run_trial(trial, *fit_args, **fit_kwargs)\n  File \"C:\\Users\\Diavolo\\miniconda3\\envs\\DataEnv\\lib\\site-packages\\keras_tuner\\engine\\tuner.py\", line 287, in run_trial\n    obj_value = self._build_and_fit_model(trial, *args, **copied_kwargs)\n  File \"C:\\Users\\Diavolo\\miniconda3\\envs\\DataEnv\\lib\\site-packages\\keras_tuner\\engine\\tuner.py\", line 214, in _build_and_fit_model\n    results = self.hypermodel.fit(hp, model, *args, **kwargs)\n  File \"C:\\Users\\Diavolo\\miniconda3\\envs\\DataEnv\\lib\\site-packages\\keras_tuner\\engine\\hypermodel.py\", line 144, in fit\n    return model.fit(*args, **kwargs)\n  File \"C:\\Users\\Diavolo\\miniconda3\\envs\\DataEnv\\lib\\site-packages\\keras\\utils\\traceback_utils.py\", line 70, in error_handler\n    raise e.with_traceback(filtered_tb) from None\n  File \"C:\\Users\\Diavolo\\miniconda3\\envs\\DataEnv\\lib\\site-packages\\tensorflow\\python\\eager\\execute.py\", line 54, in quick_execute\n    tensors = pywrap_tfe.TFE_Py_Execute(ctx._handle, device_name, op_name,\ntensorflow.python.framework.errors_impl.FailedPreconditionError: {{function_node __wrapped__SaveV2_dtypes_18_device_/job:localhost/replica:0/task:0/device:CPU:0}} Failed to rename: models\\tuned_model\\trial_4\\checkpoint_temp/part-00000-of-00001.data-00000-of-00001.tempstate18232301130315471267 to: models\\tuned_model\\trial_4\\checkpoint_temp/part-00000-of-00001.data-00000-of-00001 : The process cannot access the file because it is being used by another process.\r\n; Broken pipe [Op:SaveV2]\n"}